<?xml version="1.0"?>
<robot name="Scavbot">
  <!-- Link 0 (Base) -->
  <link name="base_link">
    <visual>
      <geometry>
        <cylinder length="8.0" radius="0.2"/>
      </geometry>
      <origin xyz="0 0 4.0" rpy="0 0 0"/>
      <material name="gray"/>
    </visual>
  </link>
  <!-- Link 1 -->
  <link name="link1">
    <visual>
      <geometry>
        <cylinder length="10.0" radius="0.2"/>
      </geometry>
      <origin xyz="0 0 5.0" rpy="0 0 0"/>
      <material name="blue"/>
    </visual>
  </link>
  <!-- Link 2 -->
  <link name="link2">
    <visual>
      <geometry>
        <cylinder length="6.0" radius="0.2"/>
      </geometry>
      <origin xyz="0 0 3.0" rpy="0 0 0"/>
      <material name="green"/>
    </visual>
  </link>
  <!-- Link 3 -->
  <link name="link3">
    <visual>
      <geometry>
        <cylinder length="4.0" radius="0.2"/>
      </geometry>
      <origin xyz="0 0 2.0" rpy="0 0 0"/>
      <material name="red"/>
    </visual>
  </link>
  <!-- Joint 0 (Base Joint) -->
  <joint name="joint0" type="revolute">
    <parent link="base_link"/>
    <child link="link1"/>
    <origin xyz="0 0 8.0" rpy="0 0 0"/>
    <axis xyz="0 0 1"/>
    <limit effort="1.0" lower="-3.14" upper="3.14" velocity="1.0"/>
  </joint>
  <!-- Joint 1 -->
  <joint name="joint1" type="revolute">
    <parent link="link1"/>
    <child link="link2"/>
    <origin xyz="0 0 10.0" rpy="0 0 0"/>
    <axis xyz="0 1 0"/>
    <limit effort="1.0" lower="-3.14" upper="3.14" velocity="1.0"/>
  </joint>
  <!-- Joint 2 -->
  <joint name="joint2" type="revolute">
    <parent link="link2"/>
    <child link="link3"/>
    <origin xyz="0 0 6.0" rpy="0 0 0"/>
    <axis xyz="0 1 0"/>
    <limit effort="1.0" lower="-3.14" upper="3.14" velocity="1.0"/>
  </joint>
  <!-- Joint 3 -->
  <joint name="joint3" type="revolute">
    <parent link="link3"/>
    <child link="link4"/>
    <origin xyz="0 0 4.0" rpy="0 0 0"/>
    <axis xyz="0 1 0"/>
    <limit effort="1.0" lower="-3.14" upper="3.14" velocity="1.0"/>
  </joint>
  <!-- End Effector -->
  <link name="link4">
    <visual>
      <geometry>
        <box size="0.2 0.2 0.2"/>
      </geometry>
      <origin xyz="0 0 0.1" rpy="0 0 0"/>
      <material name="orange"/>
    </visual>
  </link>
</robot>
